<?xml version="1.0" encoding="utf-8"?>
<!-- This URDF was automatically created by SolidWorks to URDF Exporter! Originally created by Stephen Brawner (brawner@gmail.com) 
     Commit Version: 1.5.1-0-g916b5db  Build Version: 1.5.7152.31018
     For more information, please see http://wiki.ros.org/sw_urdf_exporter -->
<robot
  name="lingao_description">
  <link
    name="base_link">
    <inertial>
      <origin
        xyz="-0.0054933 -4.1587E-05 0.062041"
        rpy="0 0 0" />
      <mass
        value="0.43668" />
      <inertia
        ixx="0.0029446"
        ixy="-1.0694E-05"
        ixz="8.6442E-05"
        iyy="0.0086395"
        iyz="-7.9718E-07"
        izz="0.0097467" />
    </inertial>
    <visual>
      <origin
        xyz="0 0 0"
        rpy="0 0 0" />
      <geometry>
        <mesh
          filename="package://lingao_description/meshes/LA_4WD_LingFeng/LingFeng_base.STL" />
      </geometry>
      <material
        name="">
        <color
          rgba="1 0.812 0 1" />
      </material>
    </visual>
    <collision>
      <origin
        xyz="0 0 0"
        rpy="0 0 0" />
      <geometry>
        <mesh
          filename="package://lingao_description/meshes/LA_4WD_LingFeng/LingFeng_base.STL" />
      </geometry>
    </collision>
  </link>
  <link
    name="wheel_la_link">
    <inertial>
      <origin
        xyz="-7.128E-08 -0.024133 -1.2354E-07"
        rpy="0 0 0" />
      <mass
        value="0.72164" />
      <inertia
        ixx="0.0014337"
        ixy="-1.4592E-09"
        ixz="1.906E-10"
        iyy="0.0026176"
        iyz="-2.5284E-09"
        izz="0.0014337" />
    </inertial>
    <visual>
      <origin
        xyz="0 0 0"
        rpy="0 0 0" />
      <geometry>
        <mesh
          filename="package://lingao_description/meshes/LA_4WD_LingFeng/wheel_left.STL" />
      </geometry>
      <material
        name="">
        <color
          rgba="0.2 0.2 0.2 1" />
      </material>
    </visual>
    <collision>
      <origin
        xyz="0 0 0"
        rpy="0 0 0" />
      <geometry>
        <mesh
          filename="package://lingao_description/meshes/LA_4WD_LingFeng/wheel_left.STL" />
      </geometry>
    </collision>
  </link>
  <joint
    name="wheel_la_joint"
    type="continuous">
    <origin
      xyz="0.12 0.1595 0.02"
      rpy="0 0 0" />
    <parent
      link="base_link" />
    <child
      link="wheel_la_link" />
    <axis
      xyz="0 1 0" />
  </joint>
  <link
    name="wheel_lb_link">
    <inertial>
      <origin
        xyz="-7.128E-08 -0.024133 -1.2354E-07"
        rpy="0 0 0" />
      <mass
        value="0.72164" />
      <inertia
        ixx="0.0014337"
        ixy="-1.4592E-09"
        ixz="1.906E-10"
        iyy="0.0026176"
        iyz="-2.5284E-09"
        izz="0.0014337" />
    </inertial>
    <visual>
      <origin
        xyz="0 0 0"
        rpy="0 0 0" />
      <geometry>
        <mesh
          filename="package://lingao_description/meshes/LA_4WD_LingFeng/wheel_left.STL" />
      </geometry>
      <material
        name="">
        <color
          rgba="0.2 0.2 0.2 1" />
      </material>
    </visual>
    <collision>
      <origin
        xyz="0 0 0"
        rpy="0 0 0" />
      <geometry>
        <mesh
          filename="package://lingao_description/meshes/LA_4WD_LingFeng/wheel_left.STL" />
      </geometry>
    </collision>
  </link>
  <joint
    name="wheel_lb_joint"
    type="continuous">
    <origin
      xyz="-0.12 0.1595 0.02"
      rpy="0 0 0" />
    <parent
      link="base_link" />
    <child
      link="wheel_lb_link" />
    <axis
      xyz="0 1 0" />
  </joint>
  <link
    name="wheel_ra_link">
    <inertial>
      <origin
        xyz="-7.1345E-08 0.024133 -1.235E-07"
        rpy="0 0 0" />
      <mass
        value="0.72164" />
      <inertia
        ixx="0.0014337"
        ixy="1.4601E-09"
        ixz="1.9073E-10"
        iyy="0.0026176"
        iyz="2.5279E-09"
        izz="0.0014337" />
    </inertial>
    <visual>
      <origin
        xyz="0 0 0"
        rpy="0 0 0" />
      <geometry>
        <mesh
          filename="package://lingao_description/meshes/LA_4WD_LingFeng/wheel_right.STL" />
      </geometry>
      <material
        name="">
        <color
          rgba="0.2 0.2 0.2 1" />
      </material>
    </visual>
    <collision>
      <origin
        xyz="0 0 0"
        rpy="0 0 0" />
      <geometry>
        <mesh
          filename="package://lingao_description/meshes/LA_4WD_LingFeng/wheel_right.STL" />
      </geometry>
    </collision>
  </link>
  <joint
    name="wheel_ra_joint"
    type="continuous">
    <origin
      xyz="0.12 -0.1595 0.02"
      rpy="0 0 0" />
    <parent
      link="base_link" />
    <child
      link="wheel_ra_link" />
    <axis
      xyz="0 1 0" />
  </joint>
  <link
    name="wheel_rb_link">
    <inertial>
      <origin
        xyz="0 0 0"
        rpy="0 0 0" />
      <mass
        value="0" />
      <inertia
        ixx="0"
        ixy="0"
        ixz="0"
        iyy="0"
        iyz="0"
        izz="0" />
    </inertial>
    <visual>
      <origin
        xyz="0 0 0"
        rpy="0 0 0" />
      <geometry>
        <mesh
          filename="package://lingao_description/meshes/LA_4WD_LingFeng/wheel_right.STL" />
      </geometry>
      <material
        name="">
        <color
          rgba="0.2 0.2 0.2 1" />
      </material>
    </visual>
    <collision>
      <origin
        xyz="0 0 0"
        rpy="0 0 0" />
      <geometry>
        <mesh
          filename="package://lingao_description/meshes/LA_4WD_LingFeng/wheel_right.STL" />
      </geometry>
    </collision>
  </link>
  <joint
    name="wheel_rb_joint"
    type="continuous">
    <origin
      xyz="-0.12 -0.1595 0.02"
      rpy="0 0 0" />
    <parent
      link="base_link" />
    <child
      link="wheel_rb_link" />
    <axis
      xyz="0 1 0" />
  </joint>
</robot>